Groq explanation saved to: artifacts/failure_explanations/groq_explanation_20251003T122435Z.json

Test: tests/generated/openapi_stubs_groq.py::test_login_wrong_password

Traceback:
Traceback (most recent call last):
  File "C:\Users\surendar\AppData\Roaming\Python\Python311\site-packages\_pytest\runner.py", line 344, in from_call
    result: TResult | None = func()
                             ^^^^^^
  File "C:\Users\surendar\AppData\Roaming\Python\Python311\site-packages\_pytest\runner.py", line 246, in <lambda>
    lambda: runtest_hook(item=item, **kwds), when=when, reraise=reraise
            ^^^^^^^^^^^^^^^^^^^^^^^^^^^^^^^
  File "C:\Users\surendar\AppData\Roaming\Python\Python311\site-packages\pluggy\_hooks.py", line 512, in __call__
    return self._hookexec(self.name, self._hookimpls.copy(), kwargs, firstresult)
           ^^^^^^^^^^^^^^^^^^^^^^^^^^^^^^^^^^^^^^^^^^^^^^^^^^^^^^^^^^^^^^^^^^^^^^
  File "C:\Users\surendar\AppData\Roaming\Python\Python311\site-packages\pluggy\_manager.py", line 120, in _hookexec
    return self._inner_hookexec(hook_name, methods, kwargs, firstresult)
           ^^^^^^^^^^^^^^^^^^^^^^^^^^^^^^^^^^^^^^^^^^^^^^^^^^^^^^^^^^^^^
  File "C:\Users\surendar\AppData\Roaming\Python\Python311\site-packages\pluggy\_callers.py", line 167, in _multicall
    raise exception
  File "C:\Users\surendar\AppData\Roaming\Python\Python311\site-packages\pluggy\_callers.py", line 139, in _multicall
    teardown.throw(exception)
  File "C:\Users\surendar\AppData\Roaming\Python\Python311\site-packages\_pytest\logging.py", line 850, in pytest_runtest_call
    yield
  File "C:\Users\surendar\AppData\Roaming\Python\Python311\site-packages\pluggy\_callers.py", line 139, in _multicall
    teardown.throw(exception)
  File "C:\Users\surendar\AppData\Roaming\Python\Python311\site-packages\_pytest\capture.py", line 900, in pytest_runtest_call
    return (yield)
            ^^^^^
  File "C:\Users\surendar\AppData\Roaming\Python\Python311\site-packages\pluggy\_callers.py", line 139, in _multicall
    teardown.throw(exception)
  File "C:\Users\surendar\AppData\Roaming\Python\Python311\site-packages\_pytest\skipping.py", line 263, in pytest_runtest_call
    return (yield)
            ^^^^^
  File "C:\Users\surendar\AppData\Roaming\Python\Python311\site-packages\pluggy\_callers.py", line 121, in _multicall
    res = hook_impl.function(*args)
          ^^^^^^^^^^^^^^^^^^^^^^^^^
  File "C:\Users\surendar\AppData\Roaming\Python\Python311\site-packages\_pytest\runner.py", line 178, in pytest_runtest_call
    item.runtest()
  File "C:\Users\surendar\AppData\Roaming\Python\Python311\site-packages\_pytest\python.py", line 1671, in runtest
    self.ihook.pytest_pyfunc_call(pyfuncitem=self)
  File "C:\Users\surendar\AppData\Roaming\Python\Python311\site-packages\pluggy\_hooks.py", line 512, in __call__
    return self._hookexec(self.name, self._hookimpls.copy(), kwargs, firstresult)
           ^^^^^^^^^^^^^^^^^^^^^^^^^^^^^^^^^^^^^^^^^^^^^^^^^^^^^^^^^^^^^^^^^^^^^^
  File "C:\Users\surendar\AppData\Roaming\Python\Python311\site-packages\pluggy\_manager.py", line 120, in _hookexec
    return self._inner_hookexec(hook_name, methods, kwargs, firstresult)
           ^^^^^^^^^^^^^^^^^^^^^^^^^^^^^^^^^^^^^^^^^^^^^^^^^^^^^^^^^^^^^
  File "C:\Users\surendar\AppData\Roaming\Python\Python311\site-packages\pluggy\_callers.py", line 167, in _multicall
    raise exception
  File "C:\Users\surendar\AppData\Roaming\Python\Python311\site-packages\pluggy\_callers.py", line 121, in _multicall
    res = hook_impl.function(*args)
          ^^^^^^^^^^^^^^^^^^^^^^^^^
  File "C:\Users\surendar\AppData\Roaming\Python\Python311\site-packages\_pytest\python.py", line 157, in pytest_pyfunc_call
    result = testfunction(**testargs)
             ^^^^^^^^^^^^^^^^^^^^^^^^
  File "D:\BONEYS\WEB\WORK\task_1\tests\generated\openapi_stubs_groq.py", line 18, in test_login_wrong_password
    assert response.status_code == 422
AssertionError: assert 401 == 422
 +  where 401 = <Response [401 Unauthorized]>.status_code

