{
  "log": "Test: tests/generated/openapi_stubs_groq.py::test_protected_endpoint_valid_token\n\nTraceback:\nTraceback (most recent call last):\n  File \"C:\\Users\\surendar\\AppData\\Roaming\\Python\\Python311\\site-packages\\_pytest\\runner.py\", line 344, in from_call\n    result: TResult | None = func()\n                             ^^^^^^\n  File \"C:\\Users\\surendar\\AppData\\Roaming\\Python\\Python311\\site-packages\\_pytest\\runner.py\", line 246, in <lambda>\n    lambda: runtest_hook(item=item, **kwds), when=when, reraise=reraise\n            ^^^^^^^^^^^^^^^^^^^^^^^^^^^^^^^\n  File \"C:\\Users\\surendar\\AppData\\Roaming\\Python\\Python311\\site-packages\\pluggy\\_hooks.py\", line 512, in __call__\n    return self._hookexec(self.name, self._hookimpls.copy(), kwargs, firstresult)\n           ^^^^^^^^^^^^^^^^^^^^^^^^^^^^^^^^^^^^^^^^^^^^^^^^^^^^^^^^^^^^^^^^^^^^^^\n  File \"C:\\Users\\surendar\\AppData\\Roaming\\Python\\Python311\\site-packages\\pluggy\\_manager.py\", line 120, in _hookexec\n    return self._inner_hookexec(hook_name, methods, kwargs, firstresult)\n           ^^^^^^^^^^^^^^^^^^^^^^^^^^^^^^^^^^^^^^^^^^^^^^^^^^^^^^^^^^^^^\n  File \"C:\\Users\\surendar\\AppData\\Roaming\\Python\\Python311\\site-packages\\pluggy\\_callers.py\", line 167, in _multicall\n    raise exception\n  File \"C:\\Users\\surendar\\AppData\\Roaming\\Python\\Python311\\site-packages\\pluggy\\_callers.py\", line 139, in _multicall\n    teardown.throw(exception)\n  File \"C:\\Users\\surendar\\AppData\\Roaming\\Python\\Python311\\site-packages\\_pytest\\logging.py\", line 850, in pytest_runtest_call\n    yield\n  File \"C:\\Users\\surendar\\AppData\\Roaming\\Python\\Python311\\site-packages\\pluggy\\_callers.py\", line 139, in _multicall\n    teardown.throw(exception)\n  File \"C:\\Users\\surendar\\AppData\\Roaming\\Python\\Python311\\site-packages\\_pytest\\capture.py\", line 900, in pytest_runtest_call\n    return (yield)\n            ^^^^^\n  File \"C:\\Users\\surendar\\AppData\\Roaming\\Python\\Python311\\site-packages\\pluggy\\_callers.py\", line 139, in _multicall\n    teardown.throw(exception)\n  File \"C:\\Users\\surendar\\AppData\\Roaming\\Python\\Python311\\site-packages\\_pytest\\skipping.py\", line 263, in pytest_runtest_call\n    return (yield)\n            ^^^^^\n  File \"C:\\Users\\surendar\\AppData\\Roaming\\Python\\Python311\\site-packages\\pluggy\\_callers.py\", line 121, in _multicall\n    res = hook_impl.function(*args)\n          ^^^^^^^^^^^^^^^^^^^^^^^^^\n  File \"C:\\Users\\surendar\\AppData\\Roaming\\Python\\Python311\\site-packages\\_pytest\\runner.py\", line 178, in pytest_runtest_call\n    item.runtest()\n  File \"C:\\Users\\surendar\\AppData\\Roaming\\Python\\Python311\\site-packages\\_pytest\\python.py\", line 1671, in runtest\n    self.ihook.pytest_pyfunc_call(pyfuncitem=self)\n  File \"C:\\Users\\surendar\\AppData\\Roaming\\Python\\Python311\\site-packages\\pluggy\\_hooks.py\", line 512, in __call__\n    return self._hookexec(self.name, self._hookimpls.copy(), kwargs, firstresult)\n           ^^^^^^^^^^^^^^^^^^^^^^^^^^^^^^^^^^^^^^^^^^^^^^^^^^^^^^^^^^^^^^^^^^^^^^\n  File \"C:\\Users\\surendar\\AppData\\Roaming\\Python\\Python311\\site-packages\\pluggy\\_manager.py\", line 120, in _hookexec\n    return self._inner_hookexec(hook_name, methods, kwargs, firstresult)\n           ^^^^^^^^^^^^^^^^^^^^^^^^^^^^^^^^^^^^^^^^^^^^^^^^^^^^^^^^^^^^^\n  File \"C:\\Users\\surendar\\AppData\\Roaming\\Python\\Python311\\site-packages\\pluggy\\_callers.py\", line 167, in _multicall\n    raise exception\n  File \"C:\\Users\\surendar\\AppData\\Roaming\\Python\\Python311\\site-packages\\pluggy\\_callers.py\", line 121, in _multicall\n    res = hook_impl.function(*args)\n          ^^^^^^^^^^^^^^^^^^^^^^^^^\n  File \"C:\\Users\\surendar\\AppData\\Roaming\\Python\\Python311\\site-packages\\_pytest\\python.py\", line 157, in pytest_pyfunc_call\n    result = testfunction(**testargs)\n             ^^^^^^^^^^^^^^^^^^^^^^^^\n  File \"D:\\BONEYS\\WEB\\WORK\\task_1\\tests\\generated\\openapi_stubs_groq.py\", line 27, in test_protected_endpoint_valid_token\n    assert response.status_code == 200\nAssertionError: assert 401 == 200\n +  where 401 = <Response [401 Unauthorized]>.status_code\n\n",
  "explanation": {
    "raw_explanation": "```json\n{\n  \"likely_cause\": \"Unauthorized access to the protected endpoint\",\n  \"quick_fix\": \"Verify the authentication token and ensure it's valid for the protected endpoint. Check the token's expiration and refresh it if necessary.\"\n}\n```\n\nExample code to verify the authentication token:\n\n```python\nimport requests\n\ndef verify_token(token):\n    try:\n        response = requests.get('https://api.example.com/protected', headers={'Authorization': f'Bearer {token}'})\n        response.raise_for_status()\n        return True\n    except requests.RequestException as e:\n        print(f\"Error verifying token: {e}\")\n        return False\n```"
  }
}