{
  "log": "Test: tests/generated/openapi_stubs_groq.py::test_moderate_endpoint_empty_text\n\nTraceback:\nTraceback (most recent call last):\n  File \"C:\\Users\\surendar\\AppData\\Roaming\\Python\\Python311\\site-packages\\_pytest\\runner.py\", line 344, in from_call\n    result: TResult | None = func()\n                             ^^^^^^\n  File \"C:\\Users\\surendar\\AppData\\Roaming\\Python\\Python311\\site-packages\\_pytest\\runner.py\", line 246, in <lambda>\n    lambda: runtest_hook(item=item, **kwds), when=when, reraise=reraise\n            ^^^^^^^^^^^^^^^^^^^^^^^^^^^^^^^\n  File \"C:\\Users\\surendar\\AppData\\Roaming\\Python\\Python311\\site-packages\\pluggy\\_hooks.py\", line 512, in __call__\n    return self._hookexec(self.name, self._hookimpls.copy(), kwargs, firstresult)\n           ^^^^^^^^^^^^^^^^^^^^^^^^^^^^^^^^^^^^^^^^^^^^^^^^^^^^^^^^^^^^^^^^^^^^^^\n  File \"C:\\Users\\surendar\\AppData\\Roaming\\Python\\Python311\\site-packages\\pluggy\\_manager.py\", line 120, in _hookexec\n    return self._inner_hookexec(hook_name, methods, kwargs, firstresult)\n           ^^^^^^^^^^^^^^^^^^^^^^^^^^^^^^^^^^^^^^^^^^^^^^^^^^^^^^^^^^^^^\n  File \"C:\\Users\\surendar\\AppData\\Roaming\\Python\\Python311\\site-packages\\pluggy\\_callers.py\", line 167, in _multicall\n    raise exception\n  File \"C:\\Users\\surendar\\AppData\\Roaming\\Python\\Python311\\site-packages\\pluggy\\_callers.py\", line 139, in _multicall\n    teardown.throw(exception)\n  File \"C:\\Users\\surendar\\AppData\\Roaming\\Python\\Python311\\site-packages\\_pytest\\logging.py\", line 850, in pytest_runtest_call\n    yield\n  File \"C:\\Users\\surendar\\AppData\\Roaming\\Python\\Python311\\site-packages\\pluggy\\_callers.py\", line 139, in _multicall\n    teardown.throw(exception)\n  File \"C:\\Users\\surendar\\AppData\\Roaming\\Python\\Python311\\site-packages\\_pytest\\capture.py\", line 900, in pytest_runtest_call\n    return (yield)\n            ^^^^^\n  File \"C:\\Users\\surendar\\AppData\\Roaming\\Python\\Python311\\site-packages\\pluggy\\_callers.py\", line 139, in _multicall\n    teardown.throw(exception)\n  File \"C:\\Users\\surendar\\AppData\\Roaming\\Python\\Python311\\site-packages\\_pytest\\skipping.py\", line 263, in pytest_runtest_call\n    return (yield)\n            ^^^^^\n  File \"C:\\Users\\surendar\\AppData\\Roaming\\Python\\Python311\\site-packages\\pluggy\\_callers.py\", line 121, in _multicall\n    res = hook_impl.function(*args)\n          ^^^^^^^^^^^^^^^^^^^^^^^^^\n  File \"C:\\Users\\surendar\\AppData\\Roaming\\Python\\Python311\\site-packages\\_pytest\\runner.py\", line 178, in pytest_runtest_call\n    item.runtest()\n  File \"C:\\Users\\surendar\\AppData\\Roaming\\Python\\Python311\\site-packages\\_pytest\\python.py\", line 1671, in runtest\n    self.ihook.pytest_pyfunc_call(pyfuncitem=self)\n  File \"C:\\Users\\surendar\\AppData\\Roaming\\Python\\Python311\\site-packages\\pluggy\\_hooks.py\", line 512, in __call__\n    return self._hookexec(self.name, self._hookimpls.copy(), kwargs, firstresult)\n           ^^^^^^^^^^^^^^^^^^^^^^^^^^^^^^^^^^^^^^^^^^^^^^^^^^^^^^^^^^^^^^^^^^^^^^\n  File \"C:\\Users\\surendar\\AppData\\Roaming\\Python\\Python311\\site-packages\\pluggy\\_manager.py\", line 120, in _hookexec\n    return self._inner_hookexec(hook_name, methods, kwargs, firstresult)\n           ^^^^^^^^^^^^^^^^^^^^^^^^^^^^^^^^^^^^^^^^^^^^^^^^^^^^^^^^^^^^^\n  File \"C:\\Users\\surendar\\AppData\\Roaming\\Python\\Python311\\site-packages\\pluggy\\_callers.py\", line 167, in _multicall\n    raise exception\n  File \"C:\\Users\\surendar\\AppData\\Roaming\\Python\\Python311\\site-packages\\pluggy\\_callers.py\", line 121, in _multicall\n    res = hook_impl.function(*args)\n          ^^^^^^^^^^^^^^^^^^^^^^^^^\n  File \"C:\\Users\\surendar\\AppData\\Roaming\\Python\\Python311\\site-packages\\_pytest\\python.py\", line 157, in pytest_pyfunc_call\n    result = testfunction(**testargs)\n             ^^^^^^^^^^^^^^^^^^^^^^^^\n  File \"D:\\BONEYS\\WEB\\WORK\\task_1\\tests\\generated\\openapi_stubs_groq.py\", line 42, in test_moderate_endpoint_empty_text\n    assert response.status_code == 422\nAssertionError: assert 400 == 422\n +  where 400 = <Response [400 Bad Request]>.status_code\n\n",
  "explanation": {
    "raw_explanation": "```json\n{\n  \"likely_cause\": \"The API endpoint returned a 400 Bad Request status code instead of the expected 422 Unprocessable Entity status code.\",\n  \"quick_fix\": \"Verify the API endpoint's expected response status code and update the test assertion accordingly. For example: `assert response.status_code == 400`.\"\n}\n```"
  }
}