{
  "log": "Test: tests/generated/openapi_stubs_groq.py::test_protected_valid_token\n\nTraceback:\nTraceback (most recent call last):\n  File \"C:\\Users\\surendar\\AppData\\Roaming\\Python\\Python311\\site-packages\\_pytest\\runner.py\", line 344, in from_call\n    result: TResult | None = func()\n                             ^^^^^^\n  File \"C:\\Users\\surendar\\AppData\\Roaming\\Python\\Python311\\site-packages\\_pytest\\runner.py\", line 246, in <lambda>\n    lambda: runtest_hook(item=item, **kwds), when=when, reraise=reraise\n            ^^^^^^^^^^^^^^^^^^^^^^^^^^^^^^^\n  File \"C:\\Users\\surendar\\AppData\\Roaming\\Python\\Python311\\site-packages\\pluggy\\_hooks.py\", line 512, in __call__\n    return self._hookexec(self.name, self._hookimpls.copy(), kwargs, firstresult)\n           ^^^^^^^^^^^^^^^^^^^^^^^^^^^^^^^^^^^^^^^^^^^^^^^^^^^^^^^^^^^^^^^^^^^^^^\n  File \"C:\\Users\\surendar\\AppData\\Roaming\\Python\\Python311\\site-packages\\pluggy\\_manager.py\", line 120, in _hookexec\n    return self._inner_hookexec(hook_name, methods, kwargs, firstresult)\n           ^^^^^^^^^^^^^^^^^^^^^^^^^^^^^^^^^^^^^^^^^^^^^^^^^^^^^^^^^^^^^\n  File \"C:\\Users\\surendar\\AppData\\Roaming\\Python\\Python311\\site-packages\\pluggy\\_callers.py\", line 167, in _multicall\n    raise exception\n  File \"C:\\Users\\surendar\\AppData\\Roaming\\Python\\Python311\\site-packages\\pluggy\\_callers.py\", line 139, in _multicall\n    teardown.throw(exception)\n  File \"C:\\Users\\surendar\\AppData\\Roaming\\Python\\Python311\\site-packages\\_pytest\\logging.py\", line 850, in pytest_runtest_call\n    yield\n  File \"C:\\Users\\surendar\\AppData\\Roaming\\Python\\Python311\\site-packages\\pluggy\\_callers.py\", line 139, in _multicall\n    teardown.throw(exception)\n  File \"C:\\Users\\surendar\\AppData\\Roaming\\Python\\Python311\\site-packages\\_pytest\\capture.py\", line 900, in pytest_runtest_call\n    return (yield)\n            ^^^^^\n  File \"C:\\Users\\surendar\\AppData\\Roaming\\Python\\Python311\\site-packages\\pluggy\\_callers.py\", line 139, in _multicall\n    teardown.throw(exception)\n  File \"C:\\Users\\surendar\\AppData\\Roaming\\Python\\Python311\\site-packages\\_pytest\\skipping.py\", line 263, in pytest_runtest_call\n    return (yield)\n            ^^^^^\n  File \"C:\\Users\\surendar\\AppData\\Roaming\\Python\\Python311\\site-packages\\pluggy\\_callers.py\", line 121, in _multicall\n    res = hook_impl.function(*args)\n          ^^^^^^^^^^^^^^^^^^^^^^^^^\n  File \"C:\\Users\\surendar\\AppData\\Roaming\\Python\\Python311\\site-packages\\_pytest\\runner.py\", line 178, in pytest_runtest_call\n    item.runtest()\n  File \"C:\\Users\\surendar\\AppData\\Roaming\\Python\\Python311\\site-packages\\_pytest\\python.py\", line 1671, in runtest\n    self.ihook.pytest_pyfunc_call(pyfuncitem=self)\n  File \"C:\\Users\\surendar\\AppData\\Roaming\\Python\\Python311\\site-packages\\pluggy\\_hooks.py\", line 512, in __call__\n    return self._hookexec(self.name, self._hookimpls.copy(), kwargs, firstresult)\n           ^^^^^^^^^^^^^^^^^^^^^^^^^^^^^^^^^^^^^^^^^^^^^^^^^^^^^^^^^^^^^^^^^^^^^^\n  File \"C:\\Users\\surendar\\AppData\\Roaming\\Python\\Python311\\site-packages\\pluggy\\_manager.py\", line 120, in _hookexec\n    return self._inner_hookexec(hook_name, methods, kwargs, firstresult)\n           ^^^^^^^^^^^^^^^^^^^^^^^^^^^^^^^^^^^^^^^^^^^^^^^^^^^^^^^^^^^^^\n  File \"C:\\Users\\surendar\\AppData\\Roaming\\Python\\Python311\\site-packages\\pluggy\\_callers.py\", line 167, in _multicall\n    raise exception\n  File \"C:\\Users\\surendar\\AppData\\Roaming\\Python\\Python311\\site-packages\\pluggy\\_callers.py\", line 121, in _multicall\n    res = hook_impl.function(*args)\n          ^^^^^^^^^^^^^^^^^^^^^^^^^\n  File \"C:\\Users\\surendar\\AppData\\Roaming\\Python\\Python311\\site-packages\\_pytest\\python.py\", line 157, in pytest_pyfunc_call\n    result = testfunction(**testargs)\n             ^^^^^^^^^^^^^^^^^^^^^^^^\n  File \"D:\\BONEYS\\WEB\\WORK\\task_1\\tests\\generated\\openapi_stubs_groq.py\", line 32, in test_protected_valid_token\n    assert token is not None\nAssertionError: assert None is not None\n\n",
  "explanation": {
    "raw_explanation": "```json\n{\n  \"likely_cause\": \"The token variable is not being set or is None\",\n  \"quick_fix\": \"Check the token variable is being set correctly in the test_protected_valid_token function. Ensure it's not being overwritten or set to None elsewhere in the code.\"\n}\n```\n\nExample code to check if the token variable is being set correctly:\n```python\ndef test_protected_valid_token():\n    token = get_token()  # assuming get_token() is a function that sets the token variable\n    assert token is not None\n```\nIf the token variable is being set correctly, the issue might be with the `get_token()` function. In that case, the quick fix would be to debug the `get_token()` function to see why it's returning None."
  }
}